/gpfs/home/jl24018/mambaforge-pypy3/envs/openmm/lib/python3.12/site-packages/Bio/PDB/PDBParser.py:384: PDBConstructionWarning: Ignoring unrecognized record 'END' at line 2033
  warnings.warn(
2024-10-10 15:56:29,932 - relax - INFO - Loading PDB file...
2024-10-10 15:56:30,026 - relax - INFO - Adding hydrogens...
2024-10-10 15:56:31,697 - relax - INFO - Adding solvent...
2024-10-10 15:56:43,256 - relax - INFO - Platform used: CUDA
2024-10-10 15:56:46,054 - relax - INFO - Minimizing energy (LBFGS) with fixed non-hydrogen atoms...
2024-10-10 15:57:37,225 - relax - INFO - Minimizing energy (LBFGS) with fixed protein atoms...
2024-10-10 15:58:44,324 - relax - INFO - Minimizing energy (LBFGS) on the whole system (protein + water)...
2024-10-10 16:01:11,421 - relax - INFO - Saving...
2024-10-10 16:01:12,578 - relax - INFO - Done
Traceback (most recent call last):
  File "/gpfs/home/jl24018/mambaforge-pypy3/envs/openmm/lib/python3.12/shutil.py", line 847, in move
    os.rename(src, real_dst)
FileNotFoundError: [Errno 2] No such file or directory: 'tmp/p53_2.xyz' -> 'output/p53_2.xyz'

During handling of the above exception, another exception occurred:

Traceback (most recent call last):
  File "/gpfs/home/jl24018/projects/openmm-md/scripts/241010_FUB/../../src/main.py", line 84, in main
    stability(
  File "/gpfs/home/jl24018/projects/openmm-md/src/stability.py", line 127, in stability
    shutil.move(f'tmp/{filename}.xyz', f'output/{filename}.xyz')
  File "/gpfs/home/jl24018/mambaforge-pypy3/envs/openmm/lib/python3.12/shutil.py", line 867, in move
    copy_function(src, real_dst)
  File "/gpfs/home/jl24018/mambaforge-pypy3/envs/openmm/lib/python3.12/shutil.py", line 475, in copy2
    copyfile(src, dst, follow_symlinks=follow_symlinks)
  File "/gpfs/home/jl24018/mambaforge-pypy3/envs/openmm/lib/python3.12/shutil.py", line 262, in copyfile
    with open(dst, 'wb') as fdst:
         ^^^^^^^^^^^^^^^
FileNotFoundError: [Errno 2] No such file or directory: 'output/p53_2.xyz'

During handling of the above exception, another exception occurred:

Traceback (most recent call last):
  File "/gpfs/home/jl24018/projects/openmm-md/scripts/241010_FUB/../../src/main.py", line 115, in <module>
    fire.Fire(main)
  File "/gpfs/home/jl24018/mambaforge-pypy3/envs/openmm/lib/python3.12/site-packages/fire/core.py", line 143, in Fire
    component_trace = _Fire(component, args, parsed_flag_args, context, name)
                      ^^^^^^^^^^^^^^^^^^^^^^^^^^^^^^^^^^^^^^^^^^^^^^^^^^^^^^^
  File "/gpfs/home/jl24018/mambaforge-pypy3/envs/openmm/lib/python3.12/site-packages/fire/core.py", line 477, in _Fire
    component, remaining_args = _CallAndUpdateTrace(
                                ^^^^^^^^^^^^^^^^^^^^
  File "/gpfs/home/jl24018/mambaforge-pypy3/envs/openmm/lib/python3.12/site-packages/fire/core.py", line 693, in _CallAndUpdateTrace
    component = fn(*varargs, **kwargs)
                ^^^^^^^^^^^^^^^^^^^^^^
  File "/gpfs/home/jl24018/projects/openmm-md/scripts/241010_FUB/../../src/main.py", line 94, in main
    run_command(f'mv tmp/{filename}.xyz output/{filename}_{dt_string}.xyz')
  File "/gpfs/home/jl24018/projects/openmm-md/scripts/241010_FUB/../../src/main.py", line 20, in run_command
    raise Exception(f"Error running command: {command}")
Exception: Error running command: mv tmp/p53_2.xyz output/p53_2_241010_160112.xyz
